<h2>ABSTRACT</h2>
<p>
  Returning from inside a finally block will cause exceptions to be lost.
</p>
<h2>EXPLANATION</h2>
<p>
  A return statement inside a finally block will cause any exception that might be thrown in the try block to be discarded.<br /><br /><b>Example 1:</b> In the following code excerpt, the <code>MagicException</code> thrown by the second call to <code>doMagic</code> with <code>true</code> passed to it will never be delivered to the caller. The return statement inside the finally block will cause the exception to be discarded.<br /><br /><pre><br />public class MagicTrick {<br /><br />public static class MagicException extends Exception { }<br /><br />public static void main(String[] args) {<br /><br />  System.out.println("Watch as this magical code makes an " +<br />                     "exception disappear before your very eyes!");<br /><br />  System.out.println("First, the kind of exception handling " +<br />                     "you're used to:");<br />  try {<br />    doMagic(false);<br />  } catch (MagicException e) {<br />    // An exception will be caught here<br />    e.printStackTrace();<br />  }<br /> <br />  System.out.println("Now, the magic:");<br />  try {<br />    doMagic(true);<br />  } catch (MagicException e) {<br />    // No exception caught here, the finally block ate it<br />    e.printStackTrace(); <br />  }<br />  System.out.println("tada!");<br />}<br /><br />public static void doMagic(boolean returnFromFinally)<br />throws MagicException {<br /><br />  try {<br />    throw new MagicException();<br />  }<br />  finally {<br />    if (returnFromFinally) {<br />      return;<br />    }<br />  }<br />}<br /><br />}<br /></pre>
</p>
<h2>REFERENCES</h2>
<p>
  
</p>