<h2>ABSTRACT</h2>
<p>
  Using a <code>throw</code> statement inside a <code>finally</code> block breaks the logical progression through the <code>try-catch-finally</code>.
</p>
<h2>EXPLANATION</h2>
<p>
  In Java, <code>finally</code> blocks are always executed after their corresponding <code>try-catch</code> blocks and are often used to free allocated resources, such as file handles or database cursors. Throwing an exception in a <code>finally</code> block can bypass critical cleanup code since normal program execution will be disrupted. <br />            <br /><b>Example 1:</b> In the following code, the call to <code>stmt.close()</code> is bypassed when the <code>FileNotFoundException</code> is thrown.<br /><pre><br />public void processTransaction(Connection conn) throws FileNotFoundException<br />{<br />FileInputStream fis = null;<br />Statement stmt = null;<br />try<br />{<br />    stmt = conn.createStatement();<br />    fis = new FileInputStream("badFile.txt");<br />    ...<br />}<br />catch (FileNotFoundException fe)<br />{<br />    log("File not found.");<br />}<br />catch (SQLException se)<br />{<br />    //handle error<br />}<br />finally<br />{<br />    if (fis == null)<br />    {<br />        throw new FileNotFoundException();<br />    }<br /><br />    if (stmt != null)<br />    {<br />        try<br />        {<br />            stmt.close();<br />        }<br />        catch (SQLException e)<br />        {<br />            log(e);<br />        }<br />    }<br />}<br />}<br /></pre>
</p>
<h2>REFERENCES</h2>
<p>
  
</p>